<robot name = "robot">
    <link name="Torso">
        <inertial>
            <origin xyz="0 0 1.5" rpy="0 0 0"/>
            <mass value="1" />
            <inertia ixx="100" ixy="0" ixz="0" iyy="100" iyz="0" izz="100" />
        </inertial>
        <visual>
            <origin xyz="0 0 1.5" rpy="0 0 0"/>
            <geometry>
                <box size="1 0.5 0.5" />
            </geometry>
            <material name="Cyan">
                <color rgba="0 1.0 1.0 1.0"/>
            </material>
        </visual>
        <collision>
            <origin xyz="0 0 1.5" rpy="0 0 0"/>
            <geometry>
                <box size="1 0.5 0.5" />
            </geometry>
        </collision>
    </link>
    <joint name="Torso_FLT" type="revolute">
       <parent link="Torso"/>
       <child  link="FLT"/>
       <origin rpy="0 0 0" xyz="-.425 0.1775 0.875"/>
       <axis xyz="0 1 0"/>
       <limit effort="0.0" lower="-3.14159" upper="3.14159" velocity="0.0"/>
    </joint>
    <link name="FLT">
        <inertial>
            <origin xyz="-0.1 0.1 0" rpy="0 0 0"/>
            <mass value="1" />
            <inertia ixx="100" ixy="0" ixz="0" iyy="100" iyz="0" izz="100" />
        </inertial>
        <visual>
            <origin xyz="-0.1 0.1 0" rpy="0 0 0"/>
            <geometry>
                <box size="0.15 0.15 0.75" />
            </geometry>
            <material name="Cyan">
                <color rgba="0 1.0 1.0 1.0"/>
            </material>
        </visual>
        <collision>
            <origin xyz="-0.1 0.1 0" rpy="0 0 0"/>
            <geometry>
                <box size="0.15 0.15 0.75" />
            </geometry>
        </collision>
    </link>
    <joint name="FLT_FLL" type="revolute">
       <parent link="FLT"/>
       <child  link="FLL"/>
       <origin rpy="0 0 0" xyz="0 0 -0.5"/>
       <axis xyz="0 1 0"/>
       <limit effort="0.0" lower="-3.14159" upper="3.14159" velocity="0.0"/>
    </joint>
    <link name="FLL">
        <inertial>
            <origin xyz="-0.1 0.1 0" rpy="0 0 0"/>
            <mass value="1" />
            <inertia ixx="100" ixy="0" ixz="0" iyy="100" iyz="0" izz="100" />
        </inertial>
        <visual>
            <origin xyz="-0.1 0.1 0" rpy="0 0 0"/>
            <geometry>
                <box size="0.1 0.1 0.5" />
            </geometry>
            <material name="Cyan">
                <color rgba="0 1.0 1.0 1.0"/>
            </material>
        </visual>
        <collision>
            <origin xyz="-0.1 0.1 0" rpy="0 0 0"/>
            <geometry>
                <box size="0.1 0.1 0.5" />
            </geometry>
        </collision>
    </link>
    <joint name="Torso_FRT" type="revolute">
       <parent link="Torso"/>
       <child  link="FRT"/>
       <origin rpy="0 0 0" xyz="-.425 -0.1775 0.875"/>
       <axis xyz="0 1 0"/>
       <limit effort="0.0" lower="-3.14159" upper="3.14159" velocity="0.0"/>
    </joint>
    <link name="FRT">
        <inertial>
            <origin xyz="-0.1 -0.1 0" rpy="0 0 0"/>
            <mass value="1" />
            <inertia ixx="100" ixy="0" ixz="0" iyy="100" iyz="0" izz="100" />
        </inertial>
        <visual>
            <origin xyz="-0.1 -0.1 0" rpy="0 0 0"/>
            <geometry>
                <box size="0.15 0.15 0.75" />
            </geometry>
            <material name="Cyan">
                <color rgba="0 1.0 1.0 1.0"/>
            </material>
        </visual>
        <collision>
            <origin xyz="-0.1 -0.1 0" rpy="0 0 0"/>
            <geometry>
                <box size="0.15 0.15 0.75" />
            </geometry>
        </collision>
    </link>
    <joint name="FRT_FRL" type="revolute">
       <parent link="FRT"/>
       <child  link="FRL"/>
       <origin rpy="0 0 0" xyz="0 0 -0.5"/>
       <axis xyz="0 1 0"/>
       <limit effort="0.0" lower="-3.14159" upper="3.14159" velocity="0.0"/>
    </joint>
    <link name="FRL">
        <inertial>
            <origin xyz="-0.1 -0.1 0" rpy="0 0 0"/>
            <mass value="1" />
            <inertia ixx="100" ixy="0" ixz="0" iyy="100" iyz="0" izz="100" />
        </inertial>
        <visual>
            <origin xyz="-0.1 -0.1 0" rpy="0 0 0"/>
            <geometry>
                <box size="0.1 0.1 0.5" />
            </geometry>
            <material name="Cyan">
                <color rgba="0 1.0 1.0 1.0"/>
            </material>
        </visual>
        <collision>
            <origin xyz="-0.1 -0.1 0" rpy="0 0 0"/>
            <geometry>
                <box size="0.1 0.1 0.5" />
            </geometry>
        </collision>
    </link>
    <joint name="Torso_BLT" type="revolute">
       <parent link="Torso"/>
       <child  link="BLT"/>
       <origin rpy="0 0 0" xyz=".425 0.1775 1"/>
       <axis xyz="0 1 0"/>
       <limit effort="0.0" lower="-3.14159" upper="3.14159" velocity="0.0"/>
    </joint>
    <link name="BLT">
        <inertial>
            <origin xyz="-0.1 0.1 0" rpy="0 0 0"/>
            <mass value="1" />
            <inertia ixx="100" ixy="0" ixz="0" iyy="100" iyz="0" izz="100" />
        </inertial>
        <visual>
            <origin xyz="-0.1 0.1 0" rpy="0 0 0"/>
            <geometry>
                <box size="0.15 0.15 0.5" />
            </geometry>
            <material name="Cyan">
                <color rgba="0 1.0 1.0 1.0"/>
            </material>
        </visual>
        <collision>
            <origin xyz="-0.1 0.1 0" rpy="0 0 0"/>
            <geometry>
                <box size="0.15 0.15 0.5" />
            </geometry>
        </collision>
    </link>
    <joint name="BLT_BLL" type="revolute">
       <parent link="BLT"/>
       <child  link="BLL"/>
       <origin rpy="0 0 0" xyz="0 0 -0.5"/>
       <axis xyz="0 1 0"/>
       <limit effort="0.0" lower="-3.14159" upper="3.14159" velocity="0.0"/>
    </joint>
    <link name="BLL">
        <inertial>
            <origin xyz="-0.1 0.1 0" rpy="0 0 0"/>
            <mass value="1" />
            <inertia ixx="100" ixy="0" ixz="0" iyy="100" iyz="0" izz="100" />
        </inertial>
        <visual>
            <origin xyz="-0.1 0.1 0" rpy="0 0 0"/>
            <geometry>
                <box size="0.1 0.1 0.5" />
            </geometry>
            <material name="Cyan">
                <color rgba="0 1.0 1.0 1.0"/>
            </material>
        </visual>
        <collision>
            <origin xyz="-0.1 0.1 0" rpy="0 0 0"/>
            <geometry>
                <box size="0.1 0.1 0.5" />
            </geometry>
        </collision>
    </link>
    <joint name="Torso_BRT" type="revolute">
       <parent link="Torso"/>
       <child  link="BRT"/>
       <origin rpy="0 0 0" xyz=".425 -0.1775 1"/>
       <axis xyz="0 1 0"/>
       <limit effort="0.0" lower="-3.14159" upper="3.14159" velocity="0.0"/>
    </joint>
    <link name="BRT">
        <inertial>
            <origin xyz="-0.1 -0.1 0" rpy="0 0 0"/>
            <mass value="1" />
            <inertia ixx="100" ixy="0" ixz="0" iyy="100" iyz="0" izz="100" />
        </inertial>
        <visual>
            <origin xyz="-0.1 -0.1 0" rpy="0 0 0"/>
            <geometry>
                <box size="0.15 0.15 0.5" />
            </geometry>
            <material name="Cyan">
                <color rgba="0 1.0 1.0 1.0"/>
            </material>
        </visual>
        <collision>
            <origin xyz="-0.1 -0.1 0" rpy="0 0 0"/>
            <geometry>
                <box size="0.15 0.15 0.5" />
            </geometry>
        </collision>
    </link>
    <joint name="BRT_BRL" type="revolute">
       <parent link="BRT"/>
       <child  link="BRL"/>
       <origin rpy="0 0 0" xyz="0 0 -0.5"/>
       <axis xyz="0 1 0"/>
       <limit effort="0.0" lower="-3.14159" upper="3.14159" velocity="0.0"/>
    </joint>
    <link name="BRL">
        <inertial>
            <origin xyz="-0.1 -0.1 0" rpy="0 0 0"/>
            <mass value="1" />
            <inertia ixx="100" ixy="0" ixz="0" iyy="100" iyz="0" izz="100" />
        </inertial>
        <visual>
            <origin xyz="-0.1 -0.1 0" rpy="0 0 0"/>
            <geometry>
                <box size="0.1 0.1 0.5" />
            </geometry>
            <material name="Cyan">
                <color rgba="0 1.0 1.0 1.0"/>
            </material>
        </visual>
        <collision>
            <origin xyz="-0.1 -0.1 0" rpy="0 0 0"/>
            <geometry>
                <box size="0.1 0.1 0.5" />
            </geometry>
        </collision>
    </link>
</robot>